File: 20240523_111311_1_1.csv
Test group name,Sample name,Length,Width,Thickness,Speed (%/min),Force cell,Données brutes,,
,,(mm),(mm),(mm),(%),(N),,,
20240523_test_1,,0,0,0,0,100,VRAI,,
,,,,,,,,,
Tableau de résultats 1,,,,,,,,,
,Sample name,Length,Speed (%/min),Thickness,Width,Waiting time,Initial length between the clamps,Date de début,Déformation 1 longueur initiale
,,(mm),(%),(mm),(mm),(s),(mm),,(mm)
1,rtv_1mm,4.77,60,1,4,0,45,23/05/2024,4.77
,,,,,,,,,
Tableau de résultats 2,,,,,,,,,
,Sample name,Thickness,Length,Initiql length between the clamps,Speed (%/min),Initial length between the clamps,Waiting time,Date de début,
,,(mm),(mm),(mm),(%),(mm),(s),,
1,rtv_1mm,1,4,4.77,60,45,0,23/05/2024,
,,,,,,,,,
Time (s),Displacement (mm),Shifted displacement 10.89 (mm),Force (N),Strain AS (%),Stress AS (kPa),Nombre total de cycles,Nombre de cycles,Extenso strain (%),
0,11.9873,22.8773,0,-463.7887,0.0052,0,0,0.0001,
1.18,12.4158,23.3058,0.0564,-454.8053,14.1054,0,0,0.8195,
2.36,13.0083,23.8983,0.1333,-442.3836,33.3185,0,0,2.1891,
3.54,13.5403,24.4303,0.1994,-431.2313,49.8547,0,0,3.4323,
4.72,14.0539,24.9439,0.2618,-420.4624,65.4527,0,0,4.5785,
5.85,14.2034,25.0934,0.2783,-417.3282,69.569,0.5,0.5,4.9784,
7.03,13.5997,24.4897,0.2033,-429.9856,50.8338,0.5,0.5,3.5973,
8.21,13.0665,23.9565,0.1363,-441.1625,34.0706,0.5,0.5,2.3195,
9.39,12.5068,23.3968,0.0646,-452.8973,16.1462,0.5,0.5,1.1001,
10.519,11.9979,22.8879,-0.0013,-463.567,-0.3244,1,1,0.0184,
11.699,12.3404,23.2304,0.0434,-456.386,10.8442,1,1,0.692,
12.879,12.9825,23.8725,0.1275,-442.925,31.8865,1,1,2.1467,
14.059,13.5183,24.4083,0.195,-431.6922,48.7441,1,1,3.3818,
15.239,14.0259,24.9159,0.2579,-421.051,64.4845,1,1,4.5893,
16.376,14.1521,25.0421,0.2717,-418.4054,67.9128,1.5,1.5,4.8918,
17.556,13.5338,24.4238,0.1947,-431.3661,48.672,1.5,1.5,3.4571,
18.736,13.0034,23.8934,0.1279,-442.4866,31.971,1.5,1.5,2.2078,
19.916,12.4465,23.3365,0.0559,-454.1608,13.9776,1.5,1.5,0.9784,
21.074,11.9864,22.8764,-0.004,-463.8081,-1.0082,2,2,0.0559,
22.254,12.481,23.371,0.0632,-453.4386,15.8091,2,2,1.0094,
23.434,13.1215,24.0115,0.1453,-440.0111,36.3193,2,2,2.4581,
24.614,13.6288,24.5188,0.2086,-429.3751,52.1588,2,2,3.7108,
25.794,14.1711,25.0611,0.2744,-418.0062,68.6113,2,2,4.87,
26.929,14.0505,24.9405,0.2598,-420.5346,64.9512,2.5,2.5,4.6428,
28.109,13.4475,24.3375,0.1834,-433.1757,45.8584,2.5,2.5,3.2022,
29.289,12.9352,23.8252,0.1181,-443.917,29.522,2.5,2.5,2.0138,
30.469,12.3774,23.2674,0.0472,-455.6094,11.8026,2.5,2.5,0.7699,
31.59,11.9681,22.8581,-0.0059,-464.1904,-1.4817,3,0,0.0244,
32.77,12.5334,23.4234,0.0687,-452.3406,17.166,3,0,1.1637,
33.95,13.1309,24.0209,0.1464,-439.8141,36.5912,3,0,2.5038,
35.13,13.6348,24.5248,0.2089,-429.2501,52.2167,3,0,3.7108,
36.31,14.168,25.058,0.2747,-418.0717,68.6698,3,0,4.8677,
37.49,14.6936,25.5836,0.3359,-407.0527,83.9681,3,0,6.087,
38.67,15.1206,26.0106,0.3844,-398.1011,96.1007,3,0,7.2307,
39.85,15.6249,26.5149,0.4408,-387.5285,110.2076,3,0,8.4336,
41.03,16.1085,26.9985,0.4925,-377.3901,123.1371,3,0,9.655,
42.157,16.1909,27.0809,0.5003,-375.663,125.0807,3.5,0.5,9.8209,
43.337,15.6513,26.5413,0.44,-386.9743,109.9932,3.5,0.5,8.471,
44.517,15.1306,26.0206,0.3814,-397.891,95.3448,3.5,0.5,7.2369,
45.697,14.6596,25.5496,0.3275,-407.7662,81.8701,3.5,0.5,6.0173,
46.877,14.1102,25.0002,0.2614,-419.2829,65.3459,3.5,0.5,4.8531,
48.057,13.5928,24.4828,0.1985,-430.1291,49.6236,3.5,0.5,3.6567,
49.237,13.0833,23.9733,0.1353,-440.8114,33.8292,3.5,0.5,2.5028,
50.417,12.5707,23.4607,0.0695,-451.5573,17.3868,3.5,0.5,1.32,
51.581,12.0284,22.9184,0,-462.9277,-0.0065,4,1,0.1592,
52.729,12.2845,23.1745,0.0339,-457.5576,8.4801,4,1,0.6294,
53.909,12.9503,23.8403,0.1216,-443.5996,30.3938,4,1,2.0704,
55.089,13.473,24.363,0.1874,-432.6416,46.8401,4,1,3.329,
56.269,13.9717,24.8617,0.2488,-422.1871,62.2022,4,1,4.5038,
57.449,14.4977,25.3877,0.3115,-411.1601,77.8792,4,1,5.6687,
58.629,14.9493,25.8393,0.3632,-401.6925,90.7967,4,1,6.8792,
59.809,15.4634,26.3534,0.4214,-390.9143,105.3476,4,1,8.0582,
60.989,15.9484,26.8384,0.4749,-380.7459,118.7127,4,1,9.2224,
62.119,16.286,27.176,0.5114,-373.6697,127.8599,4.5,1.5,10.2178,
63.299,15.9057,26.7957,0.467,-381.6415,116.7428,4.5,1.5,9.1464,
64.479,15.3552,26.2452,0.4059,-393.1832,101.4655,4.5,1.5,7.8105,
65.659,14.8388,25.7288,0.3476,-404.0079,86.9108,4.5,1.5,6.5855,
66.839,14.3899,25.2799,0.294,-413.42,73.5065,4.5,1.5,5.4349,
68.019,13.8388,24.7288,0.2283,-424.9732,57.0673,4.5,1.5,4.2717,
69.199,13.3409,24.2309,0.1664,-435.4118,41.6116,4.5,1.5,3.0447,
70.379,12.8272,23.7172,0.1015,-446.1794,25.3663,4.5,1.5,1.8776,
71.559,12.2855,23.1755,0.0326,-457.5369,8.1574,4.5,1.5,0.6951,
72.689,12.0125,22.9025,-0.0017,-463.2608,-0.4307,5,2,0.086,
73.869,12.6918,23.5818,0.087,-449.0189,21.7415,5,2,1.4773,
75.049,13.2381,24.1281,0.157,-437.5651,39.2591,5,2,2.7571,
76.229,13.7438,24.6338,0.2201,-426.964,55.0326,5,2,3.9612,
77.409,14.2727,25.1627,0.2847,-415.8767,71.1654,5,2,5.1174,
78.589,14.7651,25.6551,0.3414,-405.5541,85.3495,5,2,6.3774,
79.769,15.2334,26.1234,0.3952,-395.7356,98.7919,5,2,7.4835,
80.949,15.7196,26.6096,0.4494,-385.5432,112.3619,5,2,8.6669,
82.129,16.2179,27.1079,0.5034,-375.0963,125.8594,5,2,9.8406,
83.259,16.1841,27.0741,0.4981,-375.8059,124.5173,5.5,2.5,9.8172,
84.439,15.6209,26.5109,0.4353,-387.6113,108.8233,5.5,2.5,8.4467,
85.619,15.1034,25.9935,0.3765,-398.4602,94.1341,5.5,2.5,7.1787,
86.799,14.6136,25.5036,0.3212,-408.7287,80.305,5.5,2.5,5.9794,
87.979,14.0901,24.9801,0.258,-419.7043,64.5001,5.5,2.5,4.8339,
89.159,13.567,24.457,0.1946,-430.6713,48.6465,5.5,2.5,3.6071,
90.339,13.0708,23.9608,0.1328,-441.0728,33.2018,5.5,2.5,2.4442,
91.519,12.5504,23.4404,0.0665,-451.9834,16.6294,5.5,2.5,1.2584,
92.65,12.0429,22.9329,-0.0002,-462.6235,-0.0596,6,0,0.1633,
93.823,12.3624,23.2524,0.0436,-455.9235,10.891,6,0,0.7079,
95.003,12.9937,23.8837,0.1253,-442.6907,31.3193,6,0,2.1044,
96.183,13.4993,24.3893,0.1892,-432.0904,47.2925,6,0,3.3423,
97.363,13.9857,24.8757,0.2499,-421.894,62.4777,6,0,4.5317,
98.543,14.5381,25.4281,0.315,-410.312,78.7454,6,0,5.7285,
99.723,14.986,25.876,0.3668,-400.9218,91.6897,6,0,6.9125,
100.903,15.47,26.36,0.4219,-390.7749,105.4712,6,0,8.0692,
102.083,15.9519,26.8419,0.4743,-380.6734,118.5692,6,0,9.2472,
103.263,16.4439,27.3339,0.5267,-370.3581,131.6751,6,0,10.3961,
104.443,16.9577,27.8477,0.5805,-359.5875,145.115,6,0,11.5955,
105.623,17.47,28.36,0.6318,-348.8475,157.9606,6,0,12.8166,
106.803,17.9405,28.8305,0.678,-338.9842,169.5063,6,0,13.9649,
107.983,18.4673,29.3573,0.7286,-327.9398,182.154,6,0,15.1452,
109.163,18.9284,29.8184,0.7709,-318.2721,192.7237,6,0,16.3206,
110.343,19.385,30.275,0.8132,-308.7005,203.2954,6,0,17.5399,
111.523,19.9131,30.8031,0.86,-297.6294,215.0007,6,0,18.6633,
112.703,20.3813,31.2713,0.9002,-287.8144,225.0488,6,0,19.8696,
113.84,20.2282,31.1182,0.8853,-291.0228,221.3247,6.5,0.5,19.5053,
115.02,19.6739,30.5639,0.835,-302.6439,208.7381,6.5,0.5,18.1625,
116.2,19.1521,30.0421,0.7861,-313.5837,196.5313,6.5,0.5,16.8548,
117.38,18.6154,29.5054,0.736,-324.8351,184.0099,6.5,0.5,15.6741,
118.56,18.163,29.053,0.6915,-334.3184,172.8825,6.5,0.5,14.538,
119.74,17.6644,28.5544,0.643,-344.7719,160.7608,6.5,0.5,13.3485,
120.92,17.203,28.093,0.5955,-354.4449,148.8759,6.5,0.5,12.1286,
122.1,16.6398,27.5298,0.5381,-366.2507,134.5223,6.5,0.5,10.9673,
123.28,16.1399,27.0299,0.4849,-376.7312,121.2145,6.5,0.5,9.8226,
124.46,15.6776,26.5676,0.4338,-386.4234,108.4581,6.5,0.5,8.5859,
125.64,15.1609,26.0509,0.376,-397.2558,94.0042,6.5,0.5,7.4578,
126.82,14.7187,25.6087,0.3266,-406.5253,81.6528,6.5,0.5,6.2608,
128,14.2026,25.0926,0.2658,-417.3468,66.4538,6.5,0.5,5.1034,
129.18,13.6799,24.5699,0.2026,-428.3047,50.6606,6.5,0.5,3.8878,
130.36,13.2093,24.0993,0.1445,-438.1707,36.1272,6.5,0.5,2.7228,
131.54,12.7115,23.6015,0.0811,-448.6057,20.2796,6.5,0.5,1.5624,
132.72,12.1421,23.0321,0.0076,-460.5423,1.8905,6.5,0.5,0.3115,
133.867,12.2789,23.1689,0.028,-457.6759,7.0115,7,1,0.5143,
135.047,12.9247,23.8147,0.1122,-444.1364,28.0431,7,1,1.9943,
136.227,13.4516,24.3416,0.1793,-433.0903,44.82,7,1,3.2258,
137.407,13.9412,24.8312,0.2397,-422.8262,59.9175,7,1,4.4224,
138.587,14.5106,25.4006,0.3072,-410.8892,76.7914,7,1,5.6073,
139.767,14.9576,25.8476,0.3595,-401.5183,89.8735,7,1,6.8002,
140.947,15.446,26.336,0.4145,-391.2797,103.6375,7,1,7.9864,
142.127,15.9169,26.8069,0.4659,-381.4058,116.4836,7,1,9.152,
143.307,16.3871,27.2771,0.517,-371.5492,129.249,7,1,10.3211,
144.487,16.9101,27.8001,0.5711,-360.5846,142.7688,7,1,11.483,
145.667,17.4472,28.3372,0.6255,-349.3258,156.3644,7,1,12.7365,
146.847,17.9135,28.8035,0.6726,-339.5488,168.1378,7,1,13.8931,
148.027,18.409,29.299,0.72,-329.1619,180.0044,7,1,15.0654,
149.207,18.8528,29.7428,0.7617,-319.8569,190.4371,7,1,16.2159,
150.387,19.344,30.234,0.807,-309.5607,201.7604,7,1,17.4641,
151.567,19.8794,30.7694,0.8549,-298.3356,213.721,7,1,18.567,
152.747,20.3583,31.2483,0.8979,-288.2954,224.4721,7,1,19.7664,
153.885,20.3754,31.2654,0.8978,-287.9365,224.4544,7.5,1.5,19.816,
155.065,19.8441,30.7341,0.8488,-299.075,212.1977,7.5,1.5,18.4397,
156.245,19.294,30.184,0.7976,-310.6083,199.4023,7.5,1.5,17.188,
157.425,18.7814,29.6714,0.7498,-321.3545,187.4621,7.5,1.5,16.0399,
158.605,18.2803,29.1703,0.7015,-331.859,175.3844,7.5,1.5,14.8108,
159.785,17.782,28.672,0.6524,-342.3063,163.1111,7.5,1.5,13.6219,
160.965,17.3283,28.2183,0.6077,-351.8184,151.9374,7.5,1.5,12.4485,
162.145,16.7931,27.6831,0.5518,-363.0376,137.957,7.5,1.5,11.265,
163.325,16.318,27.208,0.5015,-372.997,125.3792,7.5,1.5,10.0791,
164.505,15.8364,26.7264,0.4506,-383.0945,112.6387,7.5,1.5,8.8902,
165.685,15.3065,26.1965,0.3913,-394.2039,97.8186,7.5,1.5,7.7146,
166.865,14.8012,25.6912,0.3354,-404.7975,83.8528,7.5,1.5,6.4843,
168.045,14.3543,25.2443,0.2822,-414.1652,70.5454,7.5,1.5,5.3814,
169.225,13.8059,24.6959,0.217,-425.6621,54.245,7.5,1.5,4.1857,
170.405,13.3398,24.2298,0.1595,-435.4331,39.8738,7.5,1.5,3.019,
171.585,12.8525,23.7425,0.0985,-445.6497,24.6357,7.5,1.5,1.8314,
172.765,12.3155,23.2055,0.0299,-456.9071,7.4773,7.5,1.5,0.6247,
173.909,12.0549,22.9449,-0.0037,-462.3719,-0.9335,8,2,0.0974,
175.089,12.7304,23.6204,0.0861,-448.2091,21.5328,8,2,1.5113,
176.269,13.2485,24.1385,0.1521,-437.349,38.0128,8,2,2.7617,
177.449,13.7396,24.6296,0.2126,-427.052,53.1575,8,2,3.9675,
178.629,14.2566,25.1466,0.2764,-416.2147,69.1121,8,2,5.125,
179.809,14.7591,25.6491,0.3348,-405.6783,83.6965,8,2,6.3599,
180.989,15.2246,26.1146,0.3889,-395.9199,97.2362,8,2,7.4743,
182.169,15.7303,26.6203,0.4443,-385.3182,111.0708,8,2,8.6672,
183.349,16.1759,27.0659,0.4924,-375.9767,123.0999,8,2,9.8185,
184.529,16.6933,27.5833,0.5475,-365.1299,136.8852,8,2,11.0603,
185.709,17.2161,28.1061,0.601,-354.1707,150.2417,8,2,12.223,
186.889,17.7042,28.5942,0.6508,-343.9362,162.7074,8,2,13.4166,
188.069,18.1882,29.0782,0.6975,-333.7898,174.383,8,2,14.5697,
189.249,18.6597,29.5497,0.7429,-323.9063,185.7304,8,2,15.7245,
190.429,19.2085,30.0985,0.7939,-312.4001,198.4837,8,2,16.9189,
191.609,19.6781,30.5681,0.8368,-302.5564,209.1904,8,2,18.0999,
192.789,20.1353,31.0253,0.8767,-292.9711,219.1681,8,2,19.3084,
193.916,20.4632,31.3532,0.9056,-286.0956,226.4094,8.5,2.5,20.076,
195.096,20.0102,30.9002,0.8634,-295.5942,215.847,8.5,2.5,18.9255,
196.276,19.4389,30.3289,0.8107,-307.571,202.6871,8.5,2.5,17.6372,
197.456,18.9764,29.8664,0.7675,-317.2661,191.8769,8.5,2.5,16.4276,
198.636,18.4292,29.3192,0.7155,-328.7381,178.8674,8.5,2.5,15.2086,
199.816,17.9432,28.8332,0.6683,-338.9263,167.078,8.5,2.5,14.0418,
200.996,17.474,28.364,0.6212,-348.7625,155.3037,8.5,2.5,12.8631,
202.176,16.9778,27.8678,0.5712,-359.166,142.7899,8.5,2.5,11.6549,
203.356,16.467,27.357,0.5174,-369.875,129.3377,8.5,2.5,10.4805,
204.536,15.9606,26.8506,0.4636,-380.4911,115.8904,8.5,2.5,9.3069,
205.716,15.468,26.358,0.4091,-390.8168,102.278,8.5,2.5,8.132,
206.896,14.9975,25.8875,0.3559,-400.6815,88.9684,8.5,2.5,6.9798,
208.076,14.5347,25.4247,0.3037,-410.3842,75.9334,8.5,2.5,5.7478,
209.256,14.011,24.901,0.2404,-421.3635,60.0881,8.5,2.5,4.5904,
210.436,13.5184,24.4084,0.1814,-431.6899,45.3536,8.5,2.5,3.3816,
211.616,13.0142,23.9042,0.1178,-442.2607,29.4398,8.5,2.5,2.259,
212.796,12.5099,23.3999,0.0542,-452.8326,13.5557,8.5,2.5,1.0556,
213.914,12.0434,22.9334,-0.0057,-462.6112,-1.4159,9,0,0.0124,
215.094,12.4894,23.3794,0.0542,-453.2631,13.5564,9,0,0.9853,
216.274,13.0796,23.9696,0.1301,-440.8889,32.5306,9,0,2.3281,
217.454,13.5906,24.4806,0.195,-430.1754,48.7463,9,0,3.5468,
218.634,14.0902,24.9802,0.2554,-419.7022,63.8586,9,0,4.6843,
219.814,14.6241,25.5141,0.3195,-408.5093,79.8817,9,0,5.9178,
220.994,15.058,25.948,0.3687,-399.4121,92.1666,9,0,7.1109,
222.174,15.5346,26.4246,0.422,-389.4217,105.5095,9,0,8.2759,
223.354,16.0514,26.9414,0.4789,-378.5864,119.7229,9,0,9.4828,
224.534,16.5452,27.4352,0.5309,-368.2346,132.7236,9,0,10.6523,
225.714,17.0435,27.9335,0.5834,-357.7891,145.846,9,0,11.7837,
226.894,17.5478,28.4378,0.6336,-347.2157,158.4071,9,0,13.028,
228.074,18.0323,28.9223,0.6816,-337.0588,170.3902,9,0,14.1858,
229.254,18.5073,29.3973,0.7278,-327.1002,181.9515,9,0,15.3613,
230.434,19.0186,29.9086,0.7747,-316.381,193.677,9,0,16.5017,
231.614,19.4831,30.3731,0.8187,-306.644,204.6826,9,0,17.6829,
232.794,20.0193,30.9093,0.8654,-295.4019,216.3625,9,0,18.9152,
233.974,20.484,31.374,0.9075,-285.6609,226.8745,9,0,20.0555,
235.154,20.9687,31.8587,0.9479,-275.4996,236.9688,9,0,21.244,
236.334,21.4451,32.3351,0.9881,-265.5113,247.014,9,0,22.3989,
237.514,21.9455,32.8355,1.0275,-255.0215,256.8666,9,0,23.6291,
238.694,22.418,33.308,1.0658,-245.1152,266.4533,9,0,24.7964,
239.874,22.9376,33.8276,1.1065,-234.2212,276.6262,9,0,25.9898,
241.054,23.4352,34.3252,1.144,-223.79,285.9953,9,0,27.1707,
242.234,23.9079,34.7979,1.179,-213.8797,294.7382,9,0,28.3168,
243.414,24.3851,35.2751,1.2135,-203.876,303.3779,9,0,29.5277,
244.55,24.6432,35.5332,1.2325,-198.4655,308.1209,9.5,0.5,30.0766,
245.73,24.0915,34.9815,1.1898,-210.0319,297.4476,9.5,0.5,28.7367,
246.91,23.5267,34.4167,1.1454,-221.8718,286.3398,9.5,0.5,27.4665,
248.09,23.019,33.909,1.1061,-232.5157,276.5368,9.5,0.5,26.2852,
249.27,22.5218,33.4118,1.0661,-242.9401,266.5187,9.5,0.5,25.0992,
250.45,22.0529,32.9429,1.0273,-252.7699,256.8218,9.5,0.5,23.9176,
251.63,21.5624,32.4524,0.9876,-263.0533,246.8937,9.5,0.5,22.75,
252.81,21.0381,31.9281,0.9438,-274.0432,235.9478,9.5,0.5,21.5291,
253.99,20.5678,31.4578,0.9024,-283.903,225.5966,9.5,0.5,20.4159,
255.17,20.076,30.966,0.8601,-294.2146,215.0365,9.5,0.5,19.1617,
256.35,19.596,30.486,0.8164,-304.2768,204.1038,9.5,0.5,18.044,
257.53,19.1182,30.0082,0.7733,-314.2927,193.3349,9.5,0.5,16.8265,
258.71,18.6042,29.4942,0.7246,-325.0699,181.139,9.5,0.5,15.6782,
259.89,18.1675,29.0575,0.6834,-334.2242,170.858,9.5,0.5,14.4905,
261.07,17.6615,28.5515,0.6323,-344.8315,158.0679,9.5,0.5,13.3347,
262.25,17.1978,28.0878,0.5869,-354.5544,146.7239,9.5,0.5,12.1316,
263.43,16.6498,27.5398,0.5305,-366.0419,132.6221,9.5,0.5,10.9298,
264.61,16.1831,27.0731,0.48,-375.8267,119.9953,9.5,0.5,9.8093,
265.79,15.6767,26.5667,0.4259,-386.4425,106.471,9.5,0.5,8.591,
266.97,15.193,26.083,0.3723,-396.5825,93.0872,9.5,0.5,7.4125,
268.15,14.7032,25.5932,0.3165,-406.8518,79.1239,9.5,0.5,6.173,
269.33,14.2106,25.1006,0.2578,-417.1787,64.4619,9.5,0.5,5.0525,
270.51,13.6991,24.5891,0.1969,-427.9009,49.2271,9.5,0.5,3.8631,
271.69,13.2357,24.1257,0.1397,-437.6161,34.9282,9.5,0.5,2.7261,
272.87,12.7011,23.5911,0.0709,-448.8239,17.7173,9.5,0.5,1.5294,
274.05,12.1898,23.0798,0.0065,-459.5435,1.6223,9.5,0.5,0.3452,
275.188,12.3137,23.2037,0.0243,-456.9453,6.0823,10,1,0.5988,
276.368,12.9661,23.8561,0.109,-443.2679,27.2381,10,1,2.0101,
277.548,13.4849,24.3749,0.175,-432.3912,43.7518,10,1,3.246,
278.728,13.9921,24.8821,0.2381,-421.7579,59.5152,10,1,4.4504,
279.908,14.5201,25.4101,0.3007,-410.6889,75.1744,10,1,5.6588,
281.088,14.9654,25.8554,0.3529,-401.3541,88.2293,10,1,6.8489,
282.268,15.468,26.358,0.4091,-390.8181,102.2689,10,1,8.0099,
283.448,15.9553,26.8453,0.4635,-380.6007,115.8725,10,1,9.1558,
284.628,16.4757,27.3657,0.5186,-369.6908,129.6422,10,1,10.3318,
285.808,16.9544,27.8444,0.569,-359.6565,142.2437,10,1,11.5214,
286.988,17.4542,28.3442,0.6194,-349.1783,154.8554,10,1,12.7277,
288.168,17.9436,28.8336,0.6678,-338.9181,166.9546,10,1,13.9066,
289.348,18.4331,29.3231,0.7149,-328.6555,178.7306,10,1,15.0617,
290.528,18.8827,29.7727,0.7577,-319.2303,189.425,10,1,16.2106,
291.708,19.3592,30.2492,0.8018,-309.2419,200.4425,10,1,17.434,
292.888,19.9017,30.7917,0.8507,-297.8679,212.667,10,1,18.6162,
294.068,20.3659,31.2559,0.8906,-288.136,222.6491,10,1,19.7913,
295.248,20.8856,31.7756,0.9365,-277.2415,234.1246,10,1,20.9709,
296.428,21.3339,32.2239,0.9741,-267.8433,243.5232,10,1,22.1634,
297.608,21.8628,32.7528,1.0175,-256.7549,254.3848,10,1,23.3298,
298.788,22.3474,33.2374,1.0566,-246.5956,264.1441,10,1,24.5486,
299.968,22.8205,33.7105,1.0935,-236.6781,273.3679,10,1,25.6972,
301.148,23.3164,34.2064,1.1325,-226.28,283.1213,10,1,26.8758,
302.328,23.7977,34.6877,1.1681,-216.1898,292.032,10,1,28.0745,
303.508,24.3062,35.1962,1.206,-205.5313,301.5034,10,1,29.2759,
304.638,24.6868,35.5768,1.2332,-197.5517,308.2885,10.5,1.5,30.2452,
305.818,24.2377,35.1277,1.1991,-206.9655,299.7673,10.5,1.5,29.0472,
306.998,23.6968,34.5868,1.1572,-218.3052,289.2954,10.5,1.5,27.7755,
308.178,23.1901,34.0801,1.1181,-228.9297,279.5295,10.5,1.5,26.5219,
309.358,22.6801,33.5701,1.0775,-239.6212,269.3625,10.5,1.5,25.3339,
310.538,22.191,33.081,1.0374,-249.8746,259.3558,10.5,1.5,24.1416,
311.718,21.7211,32.6111,0.9998,-259.726,249.9408,10.5,1.5,23.0232,
312.898,21.1879,32.0779,0.9542,-270.9031,238.5616,10.5,1.5,21.8392,
314.078,20.7456,31.6356,0.9162,-280.1763,229.0439,10.5,1.5,20.7006,
315.258,20.1918,31.0818,0.8685,-291.7857,217.122,10.5,1.5,19.3961,
316.438,19.7299,30.6199,0.8271,-301.4687,206.7772,10.5,1.5,18.3002,
317.618,19.1987,30.0887,0.7791,-312.6049,194.7818,10.5,1.5,17.0849,
318.798,18.727,29.617,0.7344,-322.4945,183.5889,10.5,1.5,15.9503,
319.978,18.2999,29.1899,0.694,-331.4486,173.5119,10.5,1.5,14.7016,
321.158,17.756,28.646,0.6418,-342.8522,160.4531,10.5,1.5,13.5567,
322.338,17.2677,28.1577,0.5918,-353.0871,147.9561,10.5,1.5,12.3638,
323.518,16.7959,27.6859,0.5434,-362.9786,135.8481,10.5,1.5,11.2192,
324.698,16.297,27.187,0.4908,-373.4391,122.6937,10.5,1.5,10.0093,
325.878,15.8268,26.7168,0.4408,-383.2957,110.1983,10.5,1.5,8.822,
327.058,15.2882,26.1782,0.3815,-394.5874,95.3745,10.5,1.5,7.632,
328.238,14.7788,25.6688,0.3231,-405.2655,80.7685,10.5,1.5,6.4176,
329.418,14.3469,25.2369,0.2731,-414.3208,68.2695,10.5,1.5,5.2977,
330.598,13.8145,24.7045,0.2088,-425.4821,52.2036,10.5,1.5,4.1502,
331.778,13.3423,24.2323,0.1509,-435.3805,37.7262,10.5,1.5,2.929,
332.958,12.8471,23.7371,0.0881,-445.7641,22.0159,10.5,1.5,1.7326,
334.138,12.3079,23.1979,0.0193,-457.0661,4.8284,10.5,1.5,0.5551,
335.285,12.2052,23.0952,0.0076,-459.2197,1.904,11,2,0.2744,
336.465,12.8505,23.7405,0.0938,-445.6926,23.4547,11,2,1.6985,
337.645,13.3773,24.2673,0.1592,-434.6483,39.802,11,2,2.9993,
338.825,13.8695,24.7595,0.2211,-424.3302,55.2842,11,2,4.1862,
340.005,14.4176,25.3076,0.2869,-412.8396,71.7168,11,2,5.3712,
341.185,14.8683,25.7583,0.3401,-403.3895,85.0219,11,2,6.5483,
342.365,15.3737,26.2637,0.3965,-392.7938,99.1191,11,2,7.7413,
343.545,15.8756,26.7656,0.4527,-382.273,113.1827,11,2,8.9601,
344.725,16.3442,27.2342,0.5033,-372.4486,125.8351,11,2,10.0793,
345.905,16.8464,27.7364,0.5551,-361.9206,138.7689,11,2,11.2902,
347.085,17.3816,28.2716,0.6106,-350.7007,152.6428,11,2,12.5027,
348.265,17.8154,28.7054,0.6535,-341.6051,163.3788,11,2,13.6172,
349.445,18.3133,29.2033,0.7026,-331.1681,175.6477,11,2,14.8328,
350.625,18.7883,29.6783,0.7469,-321.209,186.7209,11,2,15.9998,
351.805,19.2854,30.1754,0.7934,-310.7892,198.3587,11,2,17.2449,
352.985,19.8029,30.6929,0.8393,-299.9399,209.8306,11,2,18.366,
354.165,20.2843,31.1743,0.8833,-289.8464,220.8309,11,2,19.5268,
355.345,20.7861,31.6761,0.9264,-279.3272,231.5896,11,2,20.684,
356.525,21.2288,32.1188,0.9636,-270.0467,240.9065,11,2,21.8908,
357.705,21.7849,32.6749,1.0097,-258.3868,252.4132,11,2,23.1092,
358.885,22.2804,33.1704,1.0493,-247.9999,262.3158,11,2,24.26,
360.065,22.7318,33.6218,1.0854,-238.5376,271.3416,11,2,25.4094,
361.245,23.2184,34.1084,1.1225,-228.3346,280.6194,11,2,26.6017,
362.425,23.7035,34.5935,1.1597,-218.165,289.9328,11,2,27.788,
363.605,24.2004,35.0904,1.1966,-207.7482,299.1533,11,2,29.0162,
364.728,24.6804,35.5704,1.2311,-197.6853,307.7832,11.5,2.5,30.0491,
365.908,24.4254,35.3154,1.2124,-203.0323,303.091,11.5,2.5,29.5371,
367.088,23.89,34.78,1.1709,-214.2561,292.7205,11.5,2.5,28.1421,
368.268,23.3866,34.2766,1.1316,-224.8097,282.9022,11.5,2.5,26.9143,
369.448,22.8415,33.7315,1.089,-236.2376,272.2618,11.5,2.5,25.686,
370.628,22.3555,33.2455,1.0498,-246.4254,262.4384,11.5,2.5,24.4999,
371.808,21.8841,32.7741,1.0122,-256.3079,253.0405,11.5,2.5,23.3401,
372.988,21.3641,32.2541,0.9677,-267.2104,241.9133,11.5,2.5,22.1605,
374.168,20.8575,31.7475,0.9257,-277.8311,231.4185,11.5,2.5,20.9085,
375.348,20.3614,31.2514,0.882,-288.2308,220.5023,11.5,2.5,19.813,
376.528,19.8959,30.7859,0.8419,-297.9893,210.4704,11.5,2.5,18.6191,
377.708,19.3735,30.2635,0.7938,-308.9411,198.4446,11.5,2.5,17.4569,
378.888,18.9384,29.8284,0.754,-318.0629,188.5111,11.5,2.5,16.287,
380.068,18.4243,29.3143,0.7042,-328.8399,176.0447,11.5,2.5,15.075,
381.248,17.9645,28.8545,0.6605,-338.4803,165.1175,11.5,2.5,13.8923,
382.428,17.4358,28.3258,0.6079,-349.5635,151.9679,11.5,2.5,12.701,
383.608,16.9528,27.8428,0.559,-359.6891,139.7595,11.5,2.5,11.5375,
384.788,16.4416,27.3316,0.5045,-370.4059,126.1187,11.5,2.5,10.3121,
385.968,15.9421,26.8321,0.4522,-380.8776,113.058,11.5,2.5,9.1665,
387.148,15.4685,26.3585,0.3998,-390.8068,99.952,11.5,2.5,8.0218,
388.328,14.9702,25.8602,0.344,-401.2546,86.0033,11.5,2.5,6.829,
389.508,14.5177,25.4077,0.2915,-410.741,72.8778,11.5,2.5,5.6385,
390.688,13.9947,24.8847,0.23,-421.7046,57.5063,11.5,2.5,4.4923,
391.868,13.488,24.378,0.1679,-432.3281,41.9855,11.5,2.5,3.2563,
393.048,13.024,23.914,0.1099,-442.0538,27.4708,11.5,2.5,2.1207,
394.228,12.4801,23.3701,0.0397,-453.4564,9.9255,11.5,2.5,0.9148,
395.351,12.1218,23.0118,-0.0055,-460.9681,-1.3733,12,0,0.1325,
396.531,12.6724,23.5624,0.0678,-449.4265,16.9538,12,0,1.2883,
397.711,13.2547,24.1447,0.144,-437.2183,36.0038,12,0,2.629,
398.891,13.7291,24.6191,0.2021,-427.2721,50.519,12,0,3.815,
400.071,14.2531,25.1431,0.2669,-416.2876,66.7252,12,0,4.9823,
401.251,14.7418,25.6318,0.3244,-406.0428,81.1076,12,0,6.2167,
402.431,15.2043,26.0943,0.3776,-396.3461,94.3949,12,0,7.347,
403.611,15.7126,26.6026,0.4335,-385.689,108.3689,12,0,8.5521,
404.791,16.202,27.092,0.4866,-375.4306,121.6575,12,0,9.7279,
405.971,16.698,27.588,0.5394,-365.0323,134.8563,12,0,10.9198,
407.151,17.2652,28.1552,0.5981,-353.1407,149.529,12,0,12.1287,
408.331,17.7196,28.6096,0.6425,-343.6147,160.6355,12,0,13.2856,
409.511,18.1871,29.0771,0.6897,-333.8137,172.4147,12,0,14.4103,
410.691,18.658,29.548,0.7335,-323.9417,183.3861,12,0,15.6254,
411.871,19.2049,30.0949,0.7853,-312.4767,196.329,12,0,16.8532,
413.051,19.6265,30.5165,0.8244,-303.6366,206.1026,12,0,17.9617,
414.231,20.1281,31.0181,0.8679,-293.1216,216.9865,12,0,19.1624,
415.411,20.6501,31.5401,0.914,-282.1791,228.5105,12,0,20.3405,
416.591,21.0875,31.9775,0.9512,-273.0092,237.7982,12,0,21.5191,
417.771,21.5952,32.4852,0.9941,-262.3647,248.5317,12,0,22.7213,
418.951,22.1064,32.9964,1.0349,-251.6485,258.7255,12,0,23.886,
420.131,22.5592,33.4492,1.0713,-242.1554,267.8152,12,0,25.0931,
421.311,23.0716,33.9616,1.1113,-231.4121,277.8258,12,0,26.2875,
422.491,23.6059,34.4959,1.152,-220.2121,287.9971,12,0,27.4515,
423.671,24.0917,34.9817,1.1885,-210.0274,297.1192,12,0,28.5921,
424.851,24.548,35.438,1.2214,-200.4607,305.341,12,0,29.7551,
426.031,25.1012,35.9912,1.2614,-188.8629,315.3619,12,0,30.9637,
427.211,25.5918,36.4818,1.2958,-178.5791,323.942,12,0,32.1332,
428.391,26.0501,36.9401,1.3279,-168.9701,331.986,12,0,33.3983,
429.571,26.5001,37.3901,1.3569,-159.5358,339.23,12,0,34.4878,
430.751,27.0274,37.9174,1.3916,-148.4819,347.9012,12,0,35.6767,
431.931,27.5208,38.4108,1.4235,-138.1381,355.877,12,0,36.935,
433.111,27.966,38.856,1.4532,-128.8051,363.3097,12,0,37.9856,
434.291,28.5147,39.4047,1.4861,-117.3013,371.5217,12,0,39.275,
435.471,29.0157,39.9057,1.5178,-106.798,379.4547,12,0,40.4038,
436.651,29.4842,40.3742,1.5454,-96.9779,386.3611,12,0,41.5766,
437.831,29.9865,40.8765,1.5747,-86.4468,393.6871,12,0,42.8603,
439.011,30.4739,41.3639,1.6034,-76.2294,400.8483,12,0,43.9824,
440.191,30.9022,41.7922,1.6283,-67.2495,407.0814,12,0,45.1323,
441.371,31.4562,42.3462,1.6605,-55.6362,415.124,12,0,46.384,
442.551,31.8994,42.7894,1.6843,-46.3442,421.07,12,0,47.5157,
443.731,32.3712,43.2612,1.7111,-36.4524,427.7729,12,0,48.6425,
444.911,32.8961,43.7861,1.7383,-25.4492,434.5874,12,0,49.9378,
446.034,32.6691,43.5591,1.7238,-30.2074,430.962,12.5,0.5,49.3134,
447.214,32.0602,42.9502,1.6886,-42.9732,422.1553,12.5,0.5,47.9163,
448.394,31.6013,42.4913,1.6611,-52.5943,415.2775,12.5,0.5,46.6924,
449.574,31.1146,42.0046,1.6326,-62.7967,408.1519,12.5,0.5,45.5,
450.754,30.5751,41.4651,1.6011,-74.1061,400.2656,12.5,0.5,44.2226,
451.934,30.1343,41.0243,1.5732,-83.3491,393.2976,12.5,0.5,43.1247,
453.114,29.6818,40.5718,1.5456,-92.8344,386.3901,12.5,0.5,41.9403,
454.294,29.1663,40.0563,1.5126,-103.6424,378.1508,12.5,0.5,40.7415,
455.474,28.6758,39.5658,1.4819,-113.9254,370.4673,12.5,0.5,39.6325,
456.654,28.2223,39.1123,1.4535,-123.4312,363.3661,12.5,0.5,38.3872,
457.834,27.6546,38.5446,1.4167,-135.3342,354.1782,12.5,0.5,37.1826,
459.014,27.2454,38.1354,1.3893,-143.9112,347.3254,12.5,0.5,36.0009,
460.194,26.7281,37.6181,1.3547,-154.7567,338.6637,12.5,0.5,34.7884,
461.374,26.2407,37.1307,1.3214,-164.9745,330.3525,12.5,0.5,33.7226,
462.554,25.7664,36.6564,1.2887,-174.9191,322.1853,12.5,0.5,32.4809,
463.734,25.2726,36.1626,1.254,-185.2706,313.5113,12.5,0.5,31.3451,
464.914,24.7957,35.6857,1.219,-195.2674,304.7396,12.5,0.5,30.1538,
466.094,24.2813,35.1713,1.1816,-206.0523,295.3911,12.5,0.5,28.9736,
467.274,23.8313,34.7213,1.1484,-215.4873,287.1006,12.5,0.5,27.8034,
468.454,23.3364,34.2264,1.1098,-225.8609,277.4611,12.5,0.5,26.6236,
469.634,22.81,33.7,1.0696,-236.8965,267.401,12.5,0.5,25.4009,
470.814,22.2851,33.1751,1.028,-247.9009,257.0047,12.5,0.5,24.214,
471.994,21.8565,32.7465,0.9936,-256.8877,248.4073,12.5,0.5,23.0869,
473.174,21.3557,32.2457,0.952,-267.3858,237.9988,12.5,0.5,21.8984,
474.354,20.8655,31.7555,0.9101,-277.6629,227.5173,12.5,0.5,20.6883,
475.534,20.3319,31.2219,0.864,-288.8493,216.0081,12.5,0.5,19.5283,
476.714,19.8693,30.7593,0.823,-298.5471,205.7475,12.5,0.5,18.3403,
477.894,19.3444,30.2344,0.7754,-309.5509,193.8602,12.5,0.5,17.1648,
479.074,18.8931,29.7831,0.7326,-319.0134,183.1463,12.5,0.5,15.971,
480.254,18.3747,29.2647,0.6848,-329.8804,171.1887,12.5,0.5,14.7896,
481.434,17.8827,28.7727,0.6364,-340.1942,159.0897,12.5,0.5,13.6039,
482.614,17.3924,28.2824,0.5884,-350.4734,147.0983,12.5,0.5,12.4351,
483.794,16.9122,27.8022,0.5385,-360.5411,134.6365,12.5,0.5,11.2462,
484.974,16.3905,27.2805,0.485,-371.4786,121.2384,12.5,0.5,10.0479,
486.154,15.9122,26.8022,0.4331,-381.5047,108.2763,12.5,0.5,8.8979,
487.334,15.3856,26.2756,0.3744,-392.5443,93.6118,12.5,0.5,7.7106,
488.514,14.8994,25.7894,0.3201,-402.7381,80.0178,12.5,0.5,6.5372,
489.694,14.4493,25.3393,0.2674,-412.1738,66.8389,12.5,0.5,5.3645,
490.874,13.9188,24.8088,0.2047,-423.2949,51.1771,12.5,0.5,4.1857,
492.054,13.4402,24.3302,0.1458,-433.3302,36.4574,12.5,0.5,3.0107,
493.234,12.969,23.859,0.0864,-443.2074,21.5934,12.5,0.5,1.8242,
494.414,12.4473,23.3373,0.0194,-454.1447,4.8494,12.5,0.5,0.6516,
495.555,12.287,23.177,0.0003,-457.5048,0.0719,13,1,0.2829,
496.735,12.9211,23.8111,0.084,-444.2121,21.0007,13,1,1.7068,
497.915,13.4364,24.3264,0.1506,-433.4098,37.6487,13,1,2.9564,
499.095,13.9294,24.8194,0.2117,-423.0742,52.9201,13,1,4.158,
500.275,14.4619,25.3519,0.2769,-411.9097,69.2324,13,1,5.3611,
501.455,14.8965,25.7865,0.3267,-402.7993,81.6703,13,1,6.5543,
502.635,15.4197,26.3097,0.3867,-391.8296,96.6846,13,1,7.7401,
503.815,15.9091,26.7991,0.4404,-381.5705,110.1055,13,1,8.8826,
504.995,16.4205,27.3105,0.4965,-370.8494,124.129,13,1,10.0467,
506.175,16.9457,27.8357,0.551,-359.8383,137.7477,13,1,11.228,
507.355,17.4064,28.2964,0.5976,-350.1795,149.4042,13,1,12.4146,
508.535,17.8908,28.7808,0.6465,-340.0258,161.6246,13,1,13.6316,
509.715,18.3913,29.2812,0.6949,-329.5335,173.7337,13,1,14.7861,
510.895,18.8643,29.7543,0.7404,-319.6161,185.0943,13,1,15.9422,
512.075,19.3222,30.2122,0.7819,-310.0164,195.4875,13,1,17.147,
513.255,19.8791,30.7691,0.8333,-298.3408,208.3351,13,1,18.3645,
514.435,20.3551,31.2451,0.8752,-288.3622,218.7981,13,1,19.4764,
515.615,20.8328,31.7228,0.9166,-278.3475,229.138,13,1,20.6465,
516.795,21.2997,32.1897,0.9565,-268.5604,239.1208,13,1,21.8165,
517.975,21.8442,32.7342,1.001,-257.1442,250.2563,13,1,23.0172,
519.155,22.338,33.228,1.0405,-246.7929,260.1342,13,1,24.2425,
520.335,22.7982,33.6882,1.0773,-237.1445,269.3168,13,1,25.3818,
521.515,23.2771,34.1671,1.1147,-227.1052,278.6721,13,1,26.5581,
522.695,23.772,34.662,1.1519,-216.7289,287.9803,13,1,27.7856,
523.875,24.2843,35.1743,1.1904,-205.9891,297.5952,13,1,28.9796,
525.055,24.7876,35.6776,1.2264,-195.4389,306.5947,13,1,30.1429,
526.235,25.2672,36.1572,1.2619,-185.3843,315.4681,13,1,31.3242,
527.415,25.7999,36.6899,1.2983,-174.2163,324.5669,13,1,32.5246,
528.595,26.1958,37.0858,1.3255,-165.9165,331.3695,13,1,33.6981,
529.775,26.7428,37.6328,1.3627,-154.4483,340.6689,13,1,34.8712,
530.955,27.2476,38.1376,1.3959,-143.8656,348.9754,13,1,36.0213,
532.135,27.6657,38.5557,1.4229,-135.1016,355.7253,13,1,37.239,
533.315,28.1772,39.0672,1.4563,-124.3771,364.0779,13,1,38.3786,
534.495,28.6307,39.5207,1.4849,-114.8691,371.2164,13,1,39.561,
535.675,29.1418,40.0318,1.5166,-104.1552,379.1467,13,1,40.776,
536.855,29.6301,40.5201,1.5464,-93.918,386.6107,13,1,41.872,
538.035,30.1174,41.0074,1.5762,-83.7022,394.0491,13,1,43.1003,
539.215,30.5597,41.4497,1.6022,-74.4297,400.5593,13,1,44.2513,
540.395,31.0499,41.9399,1.6302,-64.1535,407.5414,13,1,45.4184,
541.575,31.5356,42.4256,1.6582,-53.9701,414.5516,13,1,46.6288,
542.755,31.9965,42.8865,1.6847,-44.3077,421.1867,13,1,47.8247,
543.935,32.567,43.457,1.7158,-32.3472,428.9611,13,1,48.9798,
545.067,33.0622,43.9522,1.7419,-21.9669,435.4717,13.5,1.5,50.1472,
546.247,32.8689,43.7589,1.7304,-26.018,432.5925,13.5,1.5,49.5989,
547.427,32.2782,43.1682,1.6963,-38.4021,424.0664,13.5,1.5,48.269,
548.607,31.7689,42.6589,1.6663,-49.0804,416.5742,13.5,1.5,46.9887,
549.787,31.3022,42.1922,1.6393,-58.8634,409.8319,13.5,1.5,45.8275,
550.967,30.7545,41.6445,1.6061,-70.3457,401.5308,13.5,1.5,44.6437,
552.147,30.3042,41.1942,1.5787,-79.7868,394.6702,13.5,1.5,43.4753,
553.327,29.8329,40.7229,1.5518,-89.6671,387.944,13.5,1.5,42.2892,
554.507,29.3463,40.2363,1.5205,-99.8678,380.1264,13.5,1.5,41.1075,
555.687,28.8878,39.7778,1.4912,-109.4807,372.8124,13.5,1.5,39.9217,
556.867,28.4034,39.2934,1.4617,-119.6344,365.4179,13.5,1.5,38.6738,
558.047,27.8776,38.7676,1.4263,-130.6575,356.5724,13.5,1.5,37.531,
559.227,27.3782,38.2682,1.3942,-141.1288,348.5475,13.5,1.5,36.324,
560.407,26.9029,37.7929,1.3628,-151.0914,340.7102,13.5,1.5,35.2265,
561.587,26.4015,37.2915,1.3292,-161.6039,332.2889,13.5,1.5,33.976,
562.767,25.9294,36.8195,1.2968,-171.5,324.1938,13.5,1.5,32.7818,
563.947,25.441,36.331,1.2618,-181.7394,315.4492,13.5,1.5,31.6636,
565.127,24.9726,35.8626,1.2282,-191.5588,307.0565,13.5,1.5,30.4824,
566.307,24.4795,35.3695,1.1923,-201.8973,298.0685,13.5,1.5,29.2953,
567.487,23.9473,34.8373,1.1531,-213.0543,288.2776,13.5,1.5,28.0473,
568.667,23.4736,34.3636,1.1162,-222.9861,279.0582,13.5,1.5,26.9117,
569.847,22.9825,33.8725,1.0795,-233.2804,269.8824,13.5,1.5,25.7654,
571.027,22.4529,33.3429,1.0369,-244.3838,259.2176,13.5,1.5,24.5315,
572.207,22.0053,32.8953,1.0019,-253.767,250.4732,13.5,1.5,23.404,
573.387,21.5001,32.3901,0.9594,-264.358,239.838,13.5,1.5,22.1902,
574.567,20.9546,31.8446,0.914,-275.7951,228.5116,13.5,1.5,20.9613,
575.747,20.5266,31.4166,0.8766,-284.7664,219.1624,13.5,1.5,19.8934,
576.927,20.0031,30.8931,0.8313,-295.7417,207.8167,13.5,1.5,18.6736,
578.107,19.5254,30.4154,0.788,-305.7573,197.0002,13.5,1.5,17.5212,
579.287,19.0453,29.9353,0.7432,-315.821,185.8006,13.5,1.5,16.2867,
580.467,18.5456,29.4356,0.697,-326.2967,174.2612,13.5,1.5,15.1423,
581.647,18.0573,28.9473,0.6496,-336.5336,162.4002,13.5,1.5,13.9465,
582.827,17.535,28.425,0.5984,-347.4853,149.5906,13.5,1.5,12.7411,
584.007,17.0929,27.9829,0.5531,-356.7518,138.286,13.5,1.5,11.5743,
585.187,16.5348,27.4248,0.4961,-368.4529,124.0245,13.5,1.5,10.3901,
586.367,16.0602,26.9502,0.4447,-378.4029,111.1848,13.5,1.5,9.2339,
587.547,15.5612,26.4512,0.3904,-388.8641,97.5987,13.5,1.5,8.0487,
588.727,15.0593,25.9493,0.3338,-399.3865,83.4479,13.5,1.5,6.8557,
589.907,14.5832,25.4732,0.2791,-409.3658,69.7682,13.5,1.5,5.6511,
591.087,14.0971,24.9871,0.2223,-419.5587,55.5707,13.5,1.5,4.5291,
592.267,13.5642,24.4542,0.1561,-430.7301,39.0297,13.5,1.5,3.2922,
593.447,13.1109,24.0009,0.1009,-440.2331,25.2147,13.5,1.5,2.1299,
594.627,12.6237,23.5137,0.0376,-450.4469,9.4019,13.5,1.5,0.9956,
595.778,12.2935,23.1835,-0.0044,-457.3683,-1.1092,14,2,0.2442,
596.958,12.857,23.747,0.0715,-445.5565,17.8854,14,2,1.3899,
598.138,13.3674,24.2574,0.1366,-434.8549,34.1612,14,2,2.7431,
599.318,13.8635,24.7535,0.1991,-424.4559,49.7828,14,2,3.9386,
600.498,14.4096,25.2996,0.2653,-413.0064,66.3317,14,2,5.114,
601.678,14.87,25.76,0.3191,-403.3542,79.7716,14,2,6.3424,
602.858,15.373,26.263,0.3771,-392.8096,94.2852,14,2,7.5179,
604.038,15.8533,26.7433,0.4302,-382.7394,107.5471,14,2,8.6818,
605.218,16.348,27.238,0.4843,-372.3692,121.0759,14,2,9.8344,
606.398,16.8453,27.7353,0.5359,-361.9424,133.9871,14,2,11.0114,
607.578,17.3588,28.2488,0.5896,-351.1786,147.3961,14,2,12.2318,
608.758,17.8356,28.7256,0.6368,-341.1814,159.2104,14,2,13.3903,
609.938,18.3371,29.2271,0.6851,-330.6683,171.2721,14,2,14.5893,
611.118,18.8272,29.7171,0.7328,-320.3952,183.2047,14,2,15.718,
612.298,19.294,30.184,0.776,-310.6073,193.9901,14,2,16.9155,
613.478,19.8241,30.7141,0.8245,-299.4951,206.1241,14,2,18.1066,
614.658,20.2652,31.1552,0.8629,-290.2473,215.7255,14,2,19.2613,
615.838,20.7624,31.6524,0.9071,-279.8232,226.7833,14,2,20.4315,
617.018,21.1961,32.0861,0.9443,-270.7311,236.0776,14,2,21.637,
618.198,21.7786,32.6686,0.9913,-258.5203,247.8372,14,2,22.837,
619.378,22.285,33.175,1.0331,-247.904,258.2833,14,2,24.0456,
620.558,22.7512,33.6412,1.0697,-238.1291,267.4127,14,2,25.1601,
621.738,23.2331,34.1231,1.1073,-228.0281,276.8207,14,2,26.3375,
622.918,23.7336,34.6236,1.1458,-217.5337,286.4435,14,2,27.5806,
624.098,24.2113,35.1013,1.1817,-207.52,295.4162,14,2,28.7446,
625.278,24.706,35.596,1.2174,-197.1497,304.3618,14,2,29.9062,
626.458,25.2259,36.1159,1.255,-186.249,313.7517,14,2,31.1341,
627.638,25.7153,36.6053,1.2903,-175.9895,322.5731,14,2,32.2595,
628.818,26.1504,37.0404,1.3185,-166.868,329.6334,14,2,33.4825,
629.998,26.6411,37.5312,1.3523,-156.5797,338.0663,14,2,34.6364,
631.178,27.1461,38.0361,1.3863,-145.9945,346.5862,14,2,35.8672,
632.358,27.5774,38.4674,1.4143,-136.9516,353.5776,14,2,36.9578,
633.538,28.134,39.024,1.4502,-125.2835,362.5578,14,2,38.1425,
634.718,28.6119,39.5019,1.4804,-115.2646,370.105,14,2,39.3661,
635.898,29.0794,39.9694,1.5092,-105.4634,377.3097,14,2,40.5159,
637.078,29.5592,40.4492,1.5391,-95.4045,384.7835,14,2,41.6832,
638.258,29.9957,40.8857,1.5658,-86.253,391.4538,14,2,42.8875,
639.438,30.4976,41.3876,1.5953,-75.7316,398.8344,14,2,44.0788,
640.618,30.9812,41.8712,1.6239,-65.5943,405.9832,14,2,45.2213,
641.798,31.5142,42.4042,1.655,-54.4197,413.7594,14,2,46.4136,
642.978,31.9604,42.8504,1.6804,-45.0648,420.096,14,2,47.6281,
644.158,32.5047,43.3946,1.7104,-33.6551,427.5898,14,2,48.7448,
645.338,33.0205,43.9105,1.7389,-22.8416,434.7177,14,2,49.9703,
646.48,32.8626,43.7526,1.728,-26.1507,432.0039,14.5,2.5,49.5765,
647.66,32.2829,43.1729,1.6943,-38.3041,423.5631,14.5,2.5,48.2391,
648.84,31.7628,42.6528,1.6651,-49.2066,416.2825,14.5,2.5,46.963,
650.02,31.2888,42.1788,1.6362,-59.144,409.0422,14.5,2.5,45.8071,
651.2,30.774,41.664,1.606,-69.9369,401.4996,14.5,2.5,44.6037,
652.38,30.3497,41.2397,1.5808,-78.8315,395.1881,14.5,2.5,43.4707,
653.56,29.8266,40.7166,1.5492,-89.7987,387.2893,14.5,2.5,42.2258,
654.74,29.3349,40.2249,1.518,-100.1063,379.4948,14.5,2.5,41.0905,
655.92,28.8823,39.7723,1.4899,-109.5958,372.4671,14.5,2.5,39.9024,
657.1,28.2997,39.1897,1.4535,-121.8096,363.3688,14.5,2.5,38.6373,
658.28,27.8856,38.7756,1.4256,-130.4902,356.3876,14.5,2.5,37.5218,
659.46,27.3646,38.2546,1.3913,-141.4134,347.8352,14.5,2.5,36.2886,
660.64,26.8927,37.7826,1.3609,-151.3071,340.2225,14.5,2.5,35.1736,
661.82,26.4109,37.3009,1.3272,-161.4069,331.7876,14.5,2.5,33.9629,
663,25.9168,36.8068,1.2931,-171.7642,323.2735,14.5,2.5,32.7886,
664.18,25.4547,36.3447,1.2618,-181.4528,315.4415,14.5,2.5,31.6478,
665.36,24.9991,35.8891,1.2287,-191.0037,307.1792,14.5,2.5,30.4296,
666.54,24.4404,35.3304,1.1878,-202.7173,296.9396,14.5,2.5,29.2508,
667.72,23.9405,34.8305,1.1505,-213.1971,287.6149,14.5,2.5,28.0356,
668.9,23.4397,34.3297,1.1121,-223.6962,278.0194,14.5,2.5,26.8567,
670.08,22.9362,33.8262,1.0737,-234.2522,268.4287,14.5,2.5,25.6972,
671.26,22.4632,33.3532,1.0366,-244.1677,259.1519,14.5,2.5,24.5673,
672.44,21.9781,32.8681,0.997,-254.337,249.2587,14.5,2.5,23.3745,
673.62,21.4872,32.3773,0.9567,-264.6279,239.1749,14.5,2.5,22.1643,
674.8,20.9573,31.8473,0.9118,-275.7382,227.9391,14.5,2.5,20.9627,
675.98,20.5076,31.3976,0.8731,-285.1656,218.2744,14.5,2.5,19.8442,
677.16,20.0327,30.9227,0.8313,-295.121,207.8214,14.5,2.5,18.6879,
678.34,19.543,30.433,0.7877,-305.3871,196.9234,14.5,2.5,17.4959,
679.52,19.0306,29.9206,0.7401,-316.129,185.0292,14.5,2.5,16.2577,
680.7,18.5177,29.4077,0.692,-326.8816,173.005,14.5,2.5,15.1272,
681.88,18.0609,28.9509,0.6478,-336.4582,161.9548,14.5,2.5,13.9014,
683.06,17.5449,28.4349,0.5975,-347.2777,149.3731,14.5,2.5,12.7227,
684.24,17.0647,27.9547,0.5484,-357.3439,137.1049,14.5,2.5,11.5151,
685.42,16.5382,27.4282,0.4932,-368.3818,123.3051,14.5,2.5,10.3612,
686.6,16.0528,26.9428,0.4404,-378.5568,110.0895,14.5,2.5,9.2378,
687.78,15.5763,26.4663,0.3906,-388.5466,97.6389,14.5,2.5,8.0309,
688.96,15.0739,25.9639,0.3338,-399.0793,83.455,14.5,2.5,6.8411,
690.14,14.5868,25.4768,0.2772,-409.2906,69.2996,14.5,2.5,5.634,
691.32,14.1091,24.9991,0.2211,-419.3062,55.2646,14.5,2.5,4.484,
692.5,13.5772,24.4672,0.1567,-430.4579,39.171,14.5,2.5,3.2794,
693.68,13.1073,23.9973,0.0975,-440.3086,24.3759,14.5,2.5,2.123,
694.86,12.6038,23.4938,0.0337,-450.8643,8.4158,14.5,2.5,0.947,
695.97,12.3175,23.2075,-0.0035,-456.8665,-0.8859,15,0,0.2544,
697.15,12.9064,23.7964,0.0756,-444.5191,18.9041,15,0,1.5723,
698.33,13.4265,24.3165,0.1429,-433.6167,35.7358,15,0,2.8868,
699.51,13.9441,24.8341,0.2073,-422.7655,51.8333,15,0,4.0631,
700.69,14.4663,25.3563,0.2709,-411.8172,67.7166,15,0,5.3015,
701.87,14.909,25.799,0.3215,-402.5375,80.3858,15,0,6.4685,
703.05,15.4183,26.3083,0.3799,-391.86,94.9827,15,0,7.6643,
704.23,15.9064,26.7964,0.4344,-381.6276,108.5898,15,0,8.8445,
705.41,16.396,27.286,0.4873,-371.3627,121.8344,15,0,9.9981,
706.59,16.9126,27.8026,0.5416,-360.5335,135.3967,15,0,11.1562,
707.77,17.4207,28.3107,0.5941,-349.8811,148.5372,15,0,12.3644,
708.95,17.9052,28.7952,0.6424,-339.7242,160.59,15,0,13.5358,
710.13,18.4045,29.2945,0.6903,-329.2565,172.5712,15,0,14.7282,
711.31,18.9018,29.7918,0.7384,-318.831,184.6046,15,0,15.8846,
712.49,19.363,30.253,0.7806,-309.1615,195.1569,15,0,17.0687,
713.67,19.8706,30.7605,0.8257,-298.521,206.423,15,0,18.3123,
714.85,20.3374,31.2274,0.868,-288.7344,217.0069,15,0,19.436,
716.03,20.8424,31.7324,0.912,-278.1467,228.0081,15,0,20.5832,
717.21,21.2707,32.1607,0.9476,-269.1667,236.9003,15,0,21.7472,
718.39,21.8339,32.7239,0.9944,-257.3609,248.6065,15,0,22.9577,
719.57,22.3156,33.2056,1.0334,-247.2614,258.3523,15,0,24.1716,
720.75,22.7779,33.6679,1.0701,-237.5701,267.5137,15,0,25.3017,
721.93,23.3081,34.1981,1.1105,-226.4559,277.6365,15,0,26.5046,
723.11,23.8005,34.6905,1.1484,-216.1318,287.0962,15,0,27.6906,
724.29,24.2687,35.1586,1.1839,-206.3176,295.9739,15,0,28.8983,
725.47,24.7885,35.6785,1.2211,-195.4202,305.2865,15,0,30.0594,
726.65,25.278,36.168,1.2565,-185.1577,314.1338,15,0,31.2626,
727.83,25.7727,36.6627,1.2911,-174.7854,322.7643,15,0,32.4278,
729.01,26.2382,37.1282,1.3236,-165.0279,330.8964,15,0,33.5647,
730.19,26.7618,37.6518,1.359,-154.051,339.7587,15,0,34.7529,
731.37,27.2598,38.1498,1.3921,-143.6102,348.0361,15,0,35.9171,
732.55,27.6893,38.5793,1.4196,-134.6052,354.8993,15,0,37.1417,
733.73,28.2189,39.1089,1.4542,-123.5027,363.5559,15,0,38.3618,
734.91,28.6644,39.5544,1.4828,-114.1637,370.7026,15,0,39.4999,
736.09,29.1563,40.0463,1.5122,-103.8515,378.0442,15,0,40.7244,
737.27,29.6777,40.5677,1.5448,-92.9205,386.1972,15,0,41.8783,
738.45,30.115,41.005,1.571,-83.7519,392.7382,15,0,43.0146,
739.63,30.6242,41.5142,1.6007,-73.0771,400.1687,15,0,44.2134,
740.81,31.0865,41.9765,1.6285,-63.3856,407.1226,15,0,45.3546,
741.99,31.6183,42.5083,1.6589,-52.2365,414.7207,15,0,46.5936,
743.17,32.0946,42.9846,1.6858,-42.2524,421.4502,15,0,47.774,
744.35,32.6053,43.4953,1.7155,-31.545,428.8678,15,0,48.9109,
745.53,33.1251,44.0151,1.7432,-20.6485,435.7924,15,0,50.1185,
746.71,33.5585,44.4485,1.7666,-11.5629,441.6621,15,0,51.3028,
747.89,34.0887,44.9787,1.7956,-0.4459,448.8943,15,0,52.4668,
749.07,34.5637,45.4537,1.8204,9.5124,455.103,15,0,53.7041,
750.25,35.0541,45.9441,1.8458,19.7916,461.455,15,0,54.844,
751.43,35.5432,46.4332,1.8706,30.0463,467.6521,15,0,56.0538,
752.61,36.0435,46.9335,1.896,40.5346,474.0009,15,0,57.2324,
753.79,36.6223,47.5123,1.9249,52.6695,481.2329,15,0,58.3448,
754.97,37.1063,47.9963,1.9486,62.8157,487.1438,15,0,59.5645,
756.15,37.6263,48.5163,1.9735,73.7169,493.3671,15,0,60.7615,
757.33,38.0573,48.9473,1.9937,82.7529,498.4363,15,0,61.9344,
758.51,38.6522,49.5422,2.0219,95.2235,505.4658,15,0,63.1251,
759.69,39.0977,49.9877,2.0425,104.5639,510.6148,15,0,64.2684,
760.87,39.5655,50.4555,2.0642,114.3706,516.0522,15,0,65.4899,
762.05,40.0949,50.9849,2.0888,125.4695,522.1924,15,0,66.6533,
763.23,40.6027,51.4927,2.1115,136.1158,527.8676,15,0,67.829,
764.41,41.1705,52.0605,2.1361,148.0182,534.0179,15,0,69.0199,
765.59,41.6308,52.5208,2.1559,157.6694,538.9871,15,0,70.2345,
766.77,42.1557,53.0457,2.1787,168.6722,544.6859,15,0,71.2547,
767.95,42.7371,53.6271,2.2037,180.861,550.9174,15,0,72.5351,
769.13,43.1168,54.0068,2.2206,188.8222,555.1614,15,0,73.5509,
770.31,43.7175,54.6075,2.2446,201.4161,561.1489,15,0,75.0448,
771.49,44.1747,55.0647,2.2641,210.9996,566.0275,15,0,76.1838,
772.67,44.7694,55.6594,2.289,223.4676,572.257,15,0,77.3518,
773.85,45.1526,56.0426,2.303,231.5005,575.7566,15,0,78.435,
775.03,45.7447,56.6347,2.3286,243.9133,582.15,15,0,79.5532,
776.16,45.7205,56.6105,2.3253,243.4071,581.3247,15.5,0.5,79.5153,
777.34,45.0528,55.9428,2.2941,229.4079,573.5226,15.5,0.5,78.2377,
778.52,44.6342,55.5242,2.275,220.6326,568.7512,15.5,0.5,76.9281,
779.7,44.1095,54.9995,2.2504,209.634,562.6119,15.5,0.5,75.8053,
780.88,43.6946,54.5846,2.2314,200.9355,557.8392,15.5,0.5,74.691,
782.06,43.2581,54.1481,2.2118,191.7832,552.946,15.5,0.5,73.5156,
783.24,42.7096,53.5996,2.1862,180.2852,546.5411,15.5,0.5,72.2885,
784.42,42.2211,53.1111,2.1633,170.045,540.8137,15.5,0.5,71.0993,
785.6,41.7439,52.6339,2.1418,160.0407,535.4564,15.5,0.5,69.9599,
786.78,41.3215,52.2115,2.1226,151.1848,530.6503,15.5,0.5,68.685,
787.96,40.8334,51.7234,2.0981,140.9516,524.5335,15.5,0.5,67.5009,
789.14,40.2885,51.1785,2.0728,129.5275,518.2027,15.5,0.5,66.3346,
790.32,39.834,50.724,2.0507,119.999,512.6752,15.5,0.5,65.2343,
791.5,39.276,50.166,2.0239,108.3028,505.968,15.5,0.5,64.0022,
792.68,38.8005,49.6905,2.0016,98.3328,500.3986,15.5,0.5,62.8611,
793.86,38.3812,49.2712,1.9811,89.5433,495.2773,15.5,0.5,61.6773,
795.04,37.7618,48.6518,1.9498,76.5573,487.4456,15.5,0.5,60.4148,
796.22,37.3518,48.2418,1.93,67.9618,482.4962,15.5,0.5,59.3105,
797.4,36.8738,47.7638,1.9057,57.9413,476.414,15.5,0.5,58.0937,
798.58,36.3815,47.2715,1.8799,47.6199,469.9847,15.5,0.5,56.9539,
799.76,35.8238,46.7138,1.8517,35.9277,462.9271,15.5,0.5,55.7548,
800.94,35.3311,46.2211,1.8272,25.6001,456.8087,15.5,0.5,54.5096,
802.12,34.8544,45.7444,1.8012,15.6058,450.3002,15.5,0.5,53.4233,
803.3,34.3639,45.2539,1.7754,5.3235,443.8598,15.5,0.5,52.2104,
804.48,33.824,44.714,1.7461,-5.996,436.52,15.5,0.5,51.0097,
805.66,33.2932,44.1832,1.717,-17.1244,429.2444,15.5,0.5,49.8603,
806.84,32.8768,43.7668,1.694,-25.8536,423.5039,15.5,0.5,48.6805,
808.02,32.3889,43.2789,1.6666,-36.0814,416.646,15.5,0.5,47.5418,
809.2,31.8237,42.7137,1.6345,-47.9311,408.6248,15.5,0.5,46.3128,
810.38,31.3324,42.2224,1.6055,-58.2302,401.3854,15.5,0.5,45.0981,
811.56,30.8268,41.7168,1.5772,-68.8309,394.2954,15.5,0.5,43.9193,
812.74,30.3452,41.2352,1.5483,-78.9272,387.0664,15.5,0.5,42.7283,
813.92,29.8653,40.7553,1.5189,-88.9883,379.7366,15.5,0.5,41.5677,
815.1,29.3938,40.2838,1.4904,-98.8718,372.5888,15.5,0.5,40.3691,
816.28,28.8664,39.7564,1.4577,-109.9293,364.4288,15.5,0.5,39.1957,
817.46,28.358,39.248,1.4246,-120.5871,356.1535,15.5,0.5,38.065,
818.64,27.8946,38.7846,1.3955,-130.3021,348.8626,15.5,0.5,36.8328,
819.82,27.3577,38.2477,1.3605,-141.5584,340.1324,15.5,0.5,35.664,
821,26.8719,37.7619,1.3269,-151.7414,331.7195,15.5,0.5,34.4754,
822.18,26.3924,37.2824,1.2946,-161.7938,323.658,15.5,0.5,33.3101,
823.36,25.8856,36.7756,1.2609,-172.4187,315.225,15.5,0.5,32.1333,
824.54,25.3623,36.2523,1.2222,-183.3895,305.5376,15.5,0.5,30.9735,
825.72,24.8867,35.7767,1.1883,-193.361,297.0716,15.5,0.5,29.8003,
826.9,24.3729,35.2629,1.1508,-204.1331,287.6998,15.5,0.5,28.5682,
828.08,23.8798,34.7698,1.1148,-214.4705,278.7016,15.5,0.5,27.4458,
829.26,23.3641,34.2542,1.0749,-225.2799,268.7183,15.5,0.5,26.2137,
830.44,22.8638,33.7538,1.0355,-235.7704,258.8824,15.5,0.5,25.0838,
831.62,22.3815,33.2715,0.9981,-245.8815,249.5283,15.5,0.5,23.884,
832.8,21.8945,32.7845,0.9575,-256.0896,239.364,15.5,0.5,22.6678,
833.98,21.413,32.303,0.9182,-266.1853,229.5448,15.5,0.5,21.5223,
835.16,20.8942,31.7842,0.8739,-277.06,218.4796,15.5,0.5,20.3272,
836.34,20.4615,31.3515,0.8366,-286.1322,209.1496,15.5,0.5,19.191,
837.52,19.9454,30.8354,0.7913,-296.951,197.823,15.5,0.5,17.979,
838.7,19.4793,30.3693,0.7484,-306.7232,187.1125,15.5,0.5,16.804,
839.88,18.9484,29.8384,0.6996,-317.8525,174.9024,15.5,0.5,15.5969,
841.06,18.4677,29.3577,0.654,-327.9301,163.4891,15.5,0.5,14.4553,
842.24,17.9669,28.8569,0.6059,-338.4302,151.4701,15.5,0.5,13.2457,
843.42,17.4792,28.3692,0.5566,-348.6543,139.1591,15.5,0.5,12.1102,
844.6,17.0027,27.8927,0.5081,-358.6442,127.0136,15.5,0.5,10.8785,
845.78,16.4861,27.3761,0.454,-369.4735,113.4879,15.5,0.5,9.7345,
846.96,16.0001,26.8901,0.4024,-379.6624,100.5961,15.5,0.5,8.54,
848.14,15.4849,26.3749,0.3464,-390.4634,86.5896,15.5,0.5,7.3544,
849.32,14.9765,25.8665,0.2877,-401.1219,71.929,15.5,0.5,6.1797,
850.5,14.5076,25.3976,0.2332,-410.9528,58.2907,15.5,0.5,5.0076,
851.68,14.0343,24.9243,0.1769,-420.8742,44.2212,15.5,0.5,3.8588,
852.86,13.5223,24.4123,0.1131,-431.6075,28.2848,15.5,0.5,2.6339,
854.04,13.0623,23.9523,0.0562,-441.2506,14.0597,15.5,0.5,1.4391,
855.18,12.6,23.49,-0.0031,-450.9434,-0.7682,16,1,0.3489,
856.36,12.9401,23.8301,0.0432,-443.8134,10.8103,16,1,1.1331,
857.54,13.4571,24.3471,0.1097,-432.9757,27.4128,16,1,2.4699,
858.72,13.9901,24.8801,0.1775,-421.8015,44.3782,16,1,3.7013,
859.9,14.4853,25.3753,0.2377,-411.4195,59.4132,16,1,4.9046,
861.08,14.9412,25.8312,0.2915,-401.8611,72.867,16,1,6.0678,
862.26,15.4494,26.3394,0.35,-391.2075,87.5056,16,1,7.2558,
863.44,15.949,26.839,0.4053,-380.7345,101.3236,16,1,8.4331,
864.62,16.4225,27.3125,0.4569,-370.8081,114.2341,16,1,9.6089,
865.8,16.9601,27.8501,0.5133,-359.536,128.3156,16,1,10.7884,
866.98,17.4157,28.3057,0.5613,-349.9861,140.3364,16,1,11.9476,
868.16,17.9309,28.8209,0.6129,-339.1842,153.2285,16,1,13.1335,
869.34,18.4147,29.3047,0.6591,-329.0429,164.7648,16,1,14.3446,
870.52,18.9178,29.8078,0.7082,-318.4944,177.0393,16,1,15.5485,
871.7,19.4376,30.3276,0.7571,-307.5975,189.2658,16,1,16.6923,
872.88,19.9254,30.8154,0.8003,-297.3706,200.0803,16,1,17.9045,
874.06,20.431,31.321,0.8461,-286.7723,211.5195,16,1,19.0622,
875.24,20.9068,31.7968,0.8872,-276.7961,221.8081,16,1,20.2866,
876.42,21.379,32.269,0.9278,-266.8972,231.9569,16,1,21.4229,
877.6,21.8612,32.7512,0.9664,-256.7879,241.6031,16,1,22.5867,
878.78,22.3239,33.2139,1.0047,-247.0875,251.1807,16,1,23.7553,
879.96,22.8099,33.6999,1.0438,-236.8998,260.9437,16,1,24.9447,
881.14,23.3168,34.2068,1.0832,-226.2717,270.8046,16,1,26.1393,
882.32,23.8297,34.7197,1.1217,-215.5194,280.417,16,1,27.297,
883.5,24.3052,35.1952,1.1581,-205.5504,289.5227,16,1,28.4656,
884.68,24.823,35.713,1.1962,-194.6956,299.0407,16,1,29.6569,
885.86,25.3302,36.2202,1.232,-184.0637,307.9973,16,1,30.8866,
887.04,25.8198,36.7098,1.2655,-173.7984,316.3873,16,1,32.0637,
888.22,26.273,37.163,1.2977,-164.2973,324.4233,16,1,33.1867,
889.4,26.7931,37.6831,1.3336,-153.3947,333.3921,16,1,34.3745,
890.58,27.2965,38.1865,1.3664,-142.8411,341.6007,16,1,35.5752,
891.76,27.7808,38.6708,1.3991,-132.6877,349.784,16,1,36.7221,
892.94,28.2761,39.1661,1.4314,-122.303,357.8389,16,1,37.9228,
894.12,28.7794,39.6694,1.4619,-111.7522,365.4829,16,1,39.1035,
895.3,29.2618,40.1518,1.4921,-101.6402,373.0364,16,1,40.2812,
896.48,29.7743,40.6643,1.5244,-90.8955,381.088,16,1,41.4711,
897.66,30.2392,41.1292,1.5522,-81.1497,388.0533,16,1,42.6372,
898.84,30.7643,41.6543,1.583,-70.1408,395.7538,16,1,43.8091,
900.02,31.2984,42.1884,1.6142,-58.944,403.5524,16,1,45.0385,
901.2,31.7166,42.6066,1.6384,-50.1752,409.6014,16,1,46.1448,
902.38,32.2525,43.1425,1.668,-38.9417,416.9998,16,1,47.3697,
903.56,32.7391,43.6291,1.6961,-28.7391,424.0332,16,1,48.5662,
904.74,33.1774,44.0674,1.7202,-19.5504,430.0499,16,1,49.7326,
905.92,33.6741,44.5641,1.7464,-9.1386,436.5997,16,1,50.8788,
907.1,34.1749,45.0649,1.7739,1.361,443.473,16,1,52.0522,
908.28,34.6818,45.5718,1.8015,11.9882,450.3849,16,1,53.3157,
909.46,35.219,46.109,1.8301,23.2499,457.514,16,1,54.5362,
910.64,35.6922,46.5822,1.8534,33.1693,463.3459,16,1,55.6489,
911.82,36.1755,47.0655,1.8777,43.3023,469.4146,16,1,56.7663,
912.855,36.8282,47.7182,-0.008,56.9851,-1.999,16,1,53.1484,